Workbook

Sheet Patent Report
A1: Questel Patent Search Report: Prior Art for ResQ-MAR (AI-Powered Multi-Agent Emergency Response System)
A2: 18 patents from the Questel export: 3 Indian patents first (shaded), then 15 international patents in the export's original order. Abstract, claim and drawback columns are excerpts; full text is on the 'Full Text' sheet.
A4: S.No | B4: Country | C4: Title | D4: Publication No. | E4: Priority Date | F4: Application Date | G4: Publication Date | H4: Current Assignee | I4: Inventors | J4: Legal Status | K4: Legal State | L4: Abstract | M4: Independent Claim (excerpt) | N4: Advantages / Previous Drawbacks (excerpt) | O4: IPC Classes | P4: Technology Domains | Q4: Image (Figure) | R4: Remarks: What ResQ-MAR Improves
A5: 1 | B5: =IF(LEFT(D5,2)="IN","India",IF(LEFT(D5,2)="US","USA",IF(LEFT(D5,2)="CN","China","Other"))) -> India | C5: A system and a method for reinforcement learning-based natural disaster relief coordination system | D5: IN202511043796 | E5: 45783 | F5: 45783 | G5: 45800 | H5: MANIPAL UNIVERSITY JAIPUR | I5: Bhavya; Pateria Nikhil | J5: Pending | K5: Alive | L5: The present invention relates to a method and system for a reinforcement learning-based natural disaster relief coordination system. The invention involves a multi-agent reinforcement learning (MARL) system for natural disaster rescue scenarios, a two-tiered decision-making framework comprising a strategic level for global resource distribution and a tactical level for localised resource optimization. This works as a cohesive state representation with heterogeneous data sources, encompassing environmental conditions, victim status, and geographic constraints, for emergency response scenarios. The system development conditions are replicated with actual disaster dynamics and survivor profiles; therefore, this facilitates real-time adaptive decision-making in the context of evolving crisis conditions, ultimately contributing to improved outcomes in emergency management. | M5: 1. A system for a reinforcement learning-based natural disaster relief coordination, comprising: a) a hierarchical multi-agent architecture; b) a state representation module; c) an action space enabling agents; d) a prioritization mechanism; e) and a learning module implementing; wherein the system operates under constrained communication conditions and is trained using simulation data for real-time, adaptive response in evolving disaster environments. | N5: Inter-coordination among various stakeholders, such as government departments, NGOs, and volunteers, is still a problem, leading to disjointed implementation and inefficient response. The most critical problem of victim prioritization based on their health condition as well as environmental conditions (such as proximity to safe locations) is still unresolved in existing systems | O5: G06N-003/092, G06N-007/01, G06N-020/00, G06Q-010/0635, G06Q-050/26 | P5: IT methods for management | R5: Closest Indian prior art on multi-agent disaster coordination. It claims a hierarchical multi-agent reinforcement-learning system, with a strategic tier for resource distribution and a tactical tier for local optimisation, trained on simulated disaster data and built for constrained communication. Its agents are learned policies, so it needs simulation and training data, and the application does not describe voice or photo intake, retrieval of official government protocols, live news or weather checks, road-network routing or regional-language dispatch. ResQ-MAR improves on this by using eight role-specialised LLM agents (Microsoft AutoGen) that cooperate through conversation instead of trained policies, so no training is needed. It converts voice and image reports into structured data, grounds each plan in NDMA procedures through ChromaDB retrieval, injects live web context, routes ambulances on a self-hosted OSRM engine and issues Telugu and Hindi dispatch with an explainable flowchart. Status is pending, so keep monitoring.
A6: 2 | B6: =IF(LEFT(D6,2)="IN","India",IF(LEFT(D6,2)="US","USA",IF(LEFT(D6,2)="CN","China","Other"))) -> India | C6: Intelligent rescue robot using NLP and optimization | D6: IN202631101067 | E6: 46255 | F6: 46255 | G6: 46262 | H6: INSTITUTE OF ENGINEERING & MANAGEMENT SCHOOL OF UNIVERSITY OF ENGINEERING & MANAGEMENT | I6: Dhar Sudipto; Paul Niladri Sekhar; Srivastava Harshit; Pradhan Buddhadeb | J6: Pending | K6: Alive | L6: An intelligent rescue robotic system for disaster response comprises an antenna (201), IoT module (202), multimodal sensors (203), microprocessor (204), analog-to-digital converter (301), power arrangement including a step-down voltage regulator (206), lithium-ion battery (206), charge controller (207) and AC mains input (208), autonomous robot (209), touch-screen display (210), routes (211, 212), and cloud database (304). The system interprets textual and spoken emergency inputs using NLP to extract victim locations, hazards and environmental conditions, and combines the interpreted information with sensorderived data. A MILP optimization model determines rescue routes, task allocations and resource distributions under time, safety and resource constraints, while a MESSP module evaluates stochastic disaster scenarios. Dynamic path planning updates navigation according to hazards and changing sensor inputs, and the IoT-connected cloud platform coordinates robotic units for victim identification, supply delivery and guided evacuation. | M6: 1. An autonomous robotic system for disaster response, comprising: an antenna (201) operatively connected to an IoT module (202) for wireless communication with a cloud database (304); a plurality of multimodal sensors (203: S1-S6) configured to acquire environmental information comprising temperature, gas concentration, vibration, structural-integrity information, acoustic information, and visual or thermal information; an analog-to-digital converter (301) configured to digitize outputs received from the plurality of multimodal sensors (203: S1-S6) and communicate corresponding digital information through a GPIO interface; a microprocessor … | N6: However, there is a demand for low-cost, easy to use, more easily adaptable technology. | O6: G01S-001/26, H01Q-003/01, H01Q-003/02, H01Q-025/04, H04N-023/00 | P6: Digital communication; Measurement; Telecommunications | R6: This Indian application describes a hardware-centred autonomous rescue robot: antenna, IoT module, multimodal sensors, microprocessor, battery power path, touch-screen and a cloud database. NLP interprets text and speech to extract victim locations and hazards, and a MILP optimisation model plans rescue routes and task allocation. Its advantage is physical reach into hazardous sites, but it depends on a purpose-built robot, a cloud database and a mathematical optimiser that is not described as cross-checked by other agents. ResQ-MAR is a software-only dispatch layer that needs no robot hardware. It separates intake, hazard checking, planning, routing and communication into eight cooperating agents, retrieves official NDMA protocols before planning, adds live web and weather awareness, calculates road routes on a local OSRM server with instant blockage recalculation, and sends regional-language dispatch. Its local Llama 3.1 and routing stack keep core operation available when internet connectivity fails.
A7: 3 | B7: =IF(LEFT(D7,2)="IN","India",IF(LEFT(D7,2)="US","USA",IF(LEFT(D7,2)="CN","China","Other"))) -> India | C7: Cloud-assisted disaster response system using swarm robotics and geospatial AI | D7: IN202641004152 | E7: 46037 | F7: 46037 | G7: 46052 | H7: Avulapati Yaswanth Kumar; Karthikeyan KMB; Rajalingam; Sekhar Chandra MVB; Stalin M; Walavalkar Prakash M | I7: Stalin M; Rajalingam; Avulapati Yaswanth Kumar; Walavalkar Prakash M; Sekhar Chandra MVB; Karthikeyan KMB | J7: Pending | K7: Alive | L7: The present invention proposes a Cloud-Assisted Disaster Response System using Swarm Robotics and Geospatial Artificial Intelligence (AI) to enable rapid, intelligent, and coordinated emergency operations during natural and man-made disasters. The system integrates autonomous swarm robotic units with cloud-based computing infrastructure and geospatial AI models to enhance situational awareness, real-time decision-making, and efficient resource deployment in disaster-affected regions. Each robotic agent in the swarm is equipped with multi-modal sensors, communication modules, and navigation capabilities to collaboratively perform tasks such as search and rescue, damage assessment, survivor localization, hazard detection, and infrastructure monitoring. Geospatial AI algorithms process real-time spatial data, including satellite imagery, aerial drone feeds, terrain maps, and sensor inputs, to generate dynamic disaster maps, predict risk zones, and optimize robot trajectories. The cloud platform provides scalable computation, data fusion, long-term storage, and global accessibility, enabling seamless coordination between swarm units, emergency responders, and command centers. Distributed intelligence within the swarm ensures fault tolerance, adaptive behavior, and continued … | M7: 1. We claim that a cloud-assisted disaster response system comprising a plurality of autonomous swarm robotic units, a cloud computing platform, and a geospatial artificial intelligence module, wherein the system is configured to perform real-time disaster monitoring, analysis, and response through coordinated multi-agent operation. 2. We claim that the swarm robotic units include aerial, ground, and amphibious robots equipped with sensors, communication modules, and onboard processors, enabling collaborative sensing, autonomous navigation, and task execution within disasteraffected environments. 3. We claim that the cloud computing platform … | N7: The convergence of cloud computing, swarm robotics, and geospatial AI presents a promising framework for achieving resilient, efficient, and intelligent disaster response operations. With the growing frequency and intensity of disasters such as earthquakes, floods, wildfires, cyclones, industrial accidents, and urban catastrophes, there is an urgent need for intelligent, autonomous, and scalable response solutions capable of operating under uncertain and dynamic conditions. | O7: B25J-009/16, G06N-003/00, G06N-003/006, G08B-021/10, H04W-004/90 | P7: Computer technology; Control; Handling; Telecommunications | R7: This pending Indian filing claims a cloud-assisted system of aerial, ground and amphibious swarm robots with a cloud platform and a geospatial AI module for monitoring, analysis and response. It targets search, rescue and damage assessment through physical robot units. The main limitations are the cost and logistics of a robot fleet and a design that depends on cloud computing, which is exactly what fails when networks go down in a disaster. ResQ-MAR uses a software swarm of eight specialised AutoGen agents rather than robots, so it can be deployed on an ordinary machine. It runs the language model locally through Ollama and routes on a self-hosted OSRM instance, which keeps core dispatch working offline. It also adds capabilities the filing does not mention: voice transcription, photo-based severity scoring, retrieval-augmented planning from official NDMA protocols, live web verification, regional-language dispatch and explainable decision flowcharts.
A8: 4 | B8: =IF(LEFT(D8,2)="IN","India",IF(LEFT(D8,2)="US","USA",IF(LEFT(D8,2)="CN","China","Other"))) -> USA | C8: Computer-implemented method and system for response time reduction in emergency incident events | D8: US12316806 | E8: 44757 | F8: 44978 | G8: 45804 | H8: ATOS PUBLIC SAFETY | I8: KOLAXIS IOANNIS; PAPADOPOULOS GAVRIIL | J8: Granted | K8: Alive | L8: A computer-implemented method and system for response-time-reduction in emergency incident events can include an artificial intelligent agent (AI Agent) that can monitor an emergency environment in real-time upon an occurrence or change in one or more emergency incident information values. The AI Agent can analyze if one or more emergency incident information values occurs and/or reaches across one or more predefined thresholds. One or more first responders can then be automatically dispatched if the analysis has shown that this is necessary. The AI Agent can be rewarded based on its performance of monitoring and/or dispatching and can adjust the one or more predefined thresholds according to the reward. | M8: 1. A computer-implemented method for response time reduction in emergency incident events comprising: monitoring, by an artificial intelligent agent (AI Agent), an emergency environment in real time upon an occurrence or change in one or more emergency incident information values; the AI Agent analyzing whether the one or more emergency incident information values occurs and/or reaches across one or more predefined thresholds; the AI Agent ad-hoc dispatching one or more first responders in response to the analysis revealing that dispatching of the one or more first responders is needed; rewarding the AI Agent with a reward based on the AI … | N8: Further, the system can be advantageously configured to communicate with one or more first responder devices or emergency department devices to notify them simultaneously in case of an identified emergency. The calls can be counted internally by the AI agent and can be clustered or categorized by location or even sub-location, to provide a better situational awareness to one or more first responder. This is especially beneficial when dealing with a large-scale critical event where multiple calls are received simultaneously, such as an earthquake, a car crash pileup, a shooting, a plane crash, etc. | O8: G06Q-010/06, G10L-015/08, G10L-015/22, H04M-003/51, H04M-011/04 | P8: Computer technology; IT methods for management; Telecommunications | R8: Granted in the US and in Europe, and still alive, so it needs careful claim-level review. An AI agent monitors the emergency environment, compares incident information values against thresholds, automatically dispatches first responders and is rewarded on its performance so that it can adjust those thresholds. It also counts and clusters calls by location. The approach centres on one agent and threshold logic, with no described use of official protocol documents, images, live web verification, road-level routing or local-language output. ResQ-MAR differs by splitting the work across eight specialised LLM agents that check each other, instead of a single reward-tuned agent. It adds Whisper voice intake, Gemini-based photo severity scoring, hazard-zone checks, retrieval of NDMA procedures from ChromaDB, live web context, OSRM route calculation and Telugu and Hindi dispatch. Operation is local-first rather than dependent on external services.
A9: 5 | B9: =IF(LEFT(D9,2)="IN","India",IF(LEFT(D9,2)="US","USA",IF(LEFT(D9,2)="CN","China","Other"))) -> USA | C9: Artificially intelligent emergency response system | D9: US20230368321 | E9: 44691 | F9: 45056 | G9: 45246 | H9: DEEP DETECTION | I9: BRINGSJORD ALEXANDER; BRINGSJORD SELMER; SPADARO PAUL; GOVINDARAJULU NAVEEN SUNDAR | J9: Pending | K9: Alive | L9: A system, method and program product for implementing an artificially intelligent emergency response system to generate a plan for an emergency event in response to received event information from one or more input devices. A process includes: translating the received event information into a logically controlled natural language; selecting a meta-model that conforms to the emergency event; generating a hypergraph model from the meta-model, wherein the hypergraph model includes details from the received event information; generating a goal based on the received event information; generating and outputting a plan to an output device based on the hypergraph model, the goal, and semantic information. | M9: 1 . An artificially intelligent emergency response system, comprising: a memory; and a processor coupled to the memory and configured to generate a plan for an emergency event in response to received event information from one or more input devices, according to a process that includes: translating the received event information into a logically controlled natural language; selecting a meta-model that conforms to the emergency event; generating a hypergraph model from the meta-model, wherein the hypergraph model includes details from the received event information; generating a goal based on the received event information; and generating and … | N9: As will be appreciated by one of skill in the art upon reading the following disclosure, various aspects described herein may be embodied as a system, a device, a method or a computer program product (e.g., a non-transitory computer-readable medium having computer executable instruction for performing the noted operations or steps). If some key capacity needed for performing one or more actions in a plan is lost, the automated reasoner will detect this inconsistency, and cause a new plan to be generated. Standard logics, e.g., first-order logic and fragments thereof, which are used in most AI work, are inadequate to capture theory of mind … | O9: G06Q-050/26 | P9: IT methods for management | R9: Pending US application from Deep Detection. It translates incoming event information into a logically controlled natural language, selects a matching meta-model, builds a hypergraph model and a goal, and generates a plan using automated reasoning, including re-planning when a key capacity is lost. Its strength is formal, verifiable reasoning, but it requires building and maintaining meta-models and logic representations, and it does not describe voice or image intake, live situational data, road routing or regional languages. ResQ-MAR achieves grounded planning differently: a Planner agent retrieves actual NDMA standard operating procedures from ChromaDB and combines them with live web information, so plans follow official guidance without hand-built logic models. The output is operational rather than abstract, because the Router agent produces an ambulance route on local OSRM data and the Comms agent translates the dispatch into Telugu and Hindi. Decisions are explained through generated flowcharts.
A10: 6 | B10: =IF(LEFT(D10,2)="IN","India",IF(LEFT(D10,2)="US","USA",IF(LEFT(D10,2)="CN","China","Other"))) -> China | C10: Safety emergency large model construction method based on artificial intelligence | D10: CN118822814 | E10: 45554 | F10: 45554 | G10: 45639 | H10: BEIJING PUJING TECHNOLOGY | I10: HOU ZHUOLIN | J10: Granted | K10: Alive | L10: The invention discloses a safety emergency large model construction method based on artificial intelligence, and relates to the technical field of safety management, the generality is extracted from various disaster scenes, the decision can be quickly adjusted only through a small amount of data in the face of brand new disasters, and the safety emergency large model construction method is high in practicability. The problem that an existing model is poor in performance when facing new natural disasters or not seeing scenes is effectively solved, the time needed by model retraining is shortened, emergency response is more flexible, multi-modal data processing is introduced, deep feature extraction is conducted on satellite images, sensor data and social media information through the CNN, and the method is more flexible and efficient. According to the method, the emergency model can more comprehensively and accurately acquire and process information from various data sources, the perception ability of the model to disaster states is greatly improved, the learning model RL is reinforced, the resource scheduling problem in a complex network structure can be better processed by combining the graph neural network GNN, and resource allocation and evacuation routes are dynamically … | M10: 1. The method for constructing the safety emergency large model based on the artificial intelligence is characterized by comprising the following steps of: step S1, multi-mode data acquisition and preprocessing, namely acquiring multi-mode data, and cleaning, denoising and uniformly formatting the multi-mode data; Step S2, initial emergency decision training of a reinforcement learning model, constructing a reinforcement learning model RL for initial training of emergency decisions based on the multi-mode data output in the step S1, and simulating emergency resource scheduling and evacuation route optimization tasks according to different … | N10: The conventional natural disaster emergency large model depends on static rules or predefined decision trees to carry out emergency response, the static rules cannot cope with complex changes among different disasters and dynamic development of emergency events, a rule set can only cover known situations, and for some emergency situations or complex environments, the conventional rule set easily causes decision errors or delays.In order to cope with the challenges, part of emergency systems start to introduce reinforcement learning, so that models can perform trial and error learning in disaster simulation, decision strategies are gradually … | O10: G06F-018/10, G06F-018/213, G06F-018/214, G06N-003/042, G06N-003/045, G06N-003/0464, G06N-003/084, G06N-003/092, G06N-003/098, G06N-003/0985, G06Q-050/26 | P10: IT methods for management | R10: Granted Chinese method for building a safety-emergency large model. It collects and cleans multimodal data, trains a reinforcement-learning decision model, and extracts generality across disasters so that decisions adapt to new disasters from a small amount of data. The aim is faster adaptation without full retraining, yet it still relies on a training pipeline, curated datasets and compute, and the model is built around Chinese deployment conditions. ResQ-MAR avoids training entirely: it uses a pretrained local Llama 3.1 model and gains disaster-specific knowledge at run time through retrieval of NDMA protocols for floods, cyclones and earthquakes, plus live web updates. New disaster types are supported by adding documents rather than retraining. It also goes beyond decision support to complete dispatch, with voice and image intake, hazard-zone checks, ambulance routing on OSRM, multilingual Indian-language output and explainable flowcharts.
A11: 7 | B11: =IF(LEFT(D11,2)="IN","India",IF(LEFT(D11,2)="US","USA",IF(LEFT(D11,2)="CN","China","Other"))) -> China | C11: Emergency resource scheduling and path planning method | D11: CN119990652 | E11: 45679 | F11: 45679 | G11: 46028 | H11: UNIVERSITY OF SCIENCE & TECHNOLOGY OF CHINA | I11: SONG JIAYUN; WEI JIUZHANG | J11: Granted | K11: Alive | L11: The invention relates to the technical field of emergency response, in particular to an emergency resource scheduling and path planning method, which comprises the following steps that a dynamic weight evaluation system is constructed based on emergency resource scheduling factors, and the weight evaluation system can dynamically calculate and adjust factor weights so as to determine that the most critical resource is scheduled to the most required place under the emergency condition; and constructing a deep reinforcement learning model, and using historical emergency response data as a training set, so that the intelligent agent learns and optimizes a strategy of selecting an optimal path under different conditions in a simulated or historical emergency scene. Efficient emergency response: through comprehensive application of a dynamic weight evaluation system and a deep reinforcement learning model, the system can quickly identify and preferentially schedule the most critical resources to the most needed place, and meanwhile, the optimal path is planned, so that the emergency response speed and efficiency are remarkably improved. | M11: 1. The emergency resource scheduling and path planning method is characterized by comprising the following steps of: Constructing a dynamic weight evaluation system based on emergency resource scheduling factors, wherein the weight evaluation system can dynamically calculate and adjust factor weights so as to determine the most critical resource to be scheduled to the most needed place in emergency; constructing a deep reinforcement learning model, and using historical emergency response data as a training set to enable an intelligent agent to learn and optimize strategies for selecting optimal paths under different conditions in a simulated … | N11: Therefore, there is a need for an emergency resource scheduling and path planning method capable of dynamically evaluating factor weights, intelligently planning optimal paths, effectively integrating multi-source heterogeneous data, feeding back scheduling effects in real time, and continuously optimizing scheduling strategies, and a system required for implementing the method. This makes the decision of the system more data-based and more scientific and reliable. The traditional fixed weight evaluation system is difficult to accurately reflect the dynamic change, so that the optimization of the resource scheduling strategy is limited.In … | O11: G06N-003/092, G06Q-010/047, G06Q-010/0631, G06Q-010/0835, G06Q-050/26 | P11: IT methods for management | R11: Granted Chinese method for emergency resource scheduling and path planning. It builds a dynamic weight evaluation system for scheduling factors, then trains a deep reinforcement-learning agent on historical emergency data to select resources and paths. It integrates multi-source data and feeds scheduling results back to improve the strategy. Its limits are the need for historical training data, the opacity of a learned policy, and no described handling of raw voice or photo reports, official protocols or local languages. ResQ-MAR performs routing with the Open Source Routing Machine running the Multi-Level Dijkstra algorithm on local OpenStreetMap data, so routes follow real roads and can be recalculated immediately when a road is marked blocked, without any training. Planning is anchored in retrieved NDMA procedures and live web information, intake accepts text, audio and images, and the final plan is explained with flowcharts and translated for local responders in India.
A12: 8 | B12: =IF(LEFT(D12,2)="IN","India",IF(LEFT(D12,2)="US","USA",IF(LEFT(D12,2)="CN","China","Other"))) -> USA | C12: Autonomous public safety answering point (PSAP) | D12: US12489845 | E12: 45826 | F12: 45826 | G12: 45993 | H12: CARBYNE | I12: DIZENGOF ALEXANDER; BERGER JR JOSEPH EMERSON | J12: Granted | K12: Alive | L12: A method, apparatus, and computer program product for autonomous public safety answering point (PSAP). Responsive to receiving emergency call(s) originating from client device(s) used to report emergency event(s), one or more artificial intelligence (AI) agents are initiated for handling the emergency call(s), the agent(s) being configured to: classify the emergency event(s) into event type(s) associated with response protocol(s) according to data extracted from the emergency call(s); initiate emergency event report interaction(s) via the client device(s) for prompting reply to query(s) relating to the emergency event(s) driven by the response protocol(s); determine event attribute(s) of the emergency event(s) according to data extracted from the reply received to the query(s); populate entry(s) of emergency event record(s) for computer aided dispatch (CAD) of responder units to emergency events; and responsive to a determination to dispatch responder unit(s) to address the emergency event(s), dispatch the responder unit(s) according to the emergency event record(s). | M12: 1. An apparatus for autonomous public safety answering point (PSAP), comprising: at least one processing circuitry adapted for: receiving at least one emergency call originating from at least one client device used to report at least one emergency event; initiating at least one artificial intelligence (AI) agent for handling the at least one emergency call, configured for: classifying the at least one emergency event into one of a plurality of event types associated with a plurality of response protocols according to data extracted from the at least one emergency call; initiating at least one emergency event report interaction via the at … | N12: Importantly, it will be appreciated in this context that a tool call may differ from a traditional, hard-coded Application Programming Interface (API) request and/or the like. In some embodiments, the response protocol driven agent may be configured at this stage, with the emergency event fully classified (i.e., type, priority, etc.) and all key information gathered (i.e., most relevant event attributes, such as location, casualties, etc.), to provide any necessary immediate instructions to the caller (i.e., pre-arrival instructions), and/or finalize data entry in the emergency incident record for usage in CAD report context, i.e., by … | O12: G06Q-050/26, H04M-003/51, H04W-004/90 | P12: IT methods for management; Telecommunications | R12: Granted US patent for an autonomous public safety answering point. AI agents handle incoming emergency calls, classify the event type against response protocols, interact with the caller to collect missing details, and use tool calls to act on the collected information. It is the closest art on automated call intake. Its focus is the call-handling stage, and the data does not describe photo-based severity assessment, geospatial hazard-zone checks, live web verification or regional-language dispatch plans, nor local offline operation. ResQ-MAR extends beyond intake into a full pipeline: Whisper transcribes calls, a Vision agent scores damage from images, a Metadata agent produces strict JSON with coordinates, shapely checks hazard zones, a Planner agent retrieves NDMA procedures, the Router calculates an ambulance route on local OSRM, and the Comms agent translates dispatch into Telugu and Hindi. Claims should be compared carefully.
A13: 9 | B13: =IF(LEFT(D13,2)="IN","India",IF(LEFT(D13,2)="US","USA",IF(LEFT(D13,2)="CN","China","Other"))) -> China | C13: Intelligent emergency method and system based on AI large model | D13: CN122367700 | E13: 46150 | F13: 46150 | G13: 46213 | H13: SHENZHEN LIANGONG TECHNOLOGY GROUP | I13: DENG YUANZHI; DENG YUE; TIAN SONG; PENG WENLONG; WANG SENCAI | J13: Lapsed | K13: Dead | L13: The invention discloses an intelligent emergency method and system based on an AI large model, particularly relates to the technical field of emergency management, and is used for solving the problems of insufficient emergency decision intelligence, multi-source data splitting, extensive emergency material management and control, emergency function splitting and poor communication reliability in existing emergency management. Dependence on manual decision making is reduced through an AI large model, unified management and real-time synchronization of data are realized, a cooperative blind area is eliminated, intelligent checking and distribution tracing of emergency materials are realized through AI large model video identification, and second-level mode switching, quick verification-free quick material distribution and linkage of emergency resources are realized through a level-urgent dual-mode integrated architecture. Materials and equipment are intelligently managed at ordinary times, a network socket full-duplex communication and hierarchical message mechanism is adopted, emergency instructions are ensured to be transmitted preferentially, meanwhile, multi-terminal real-time cooperation is supported, and the problems that emergency decision intelligence is insufficient, … | M13: 1. An intelligent emergency method based on an AI large model is characterized by comprising the following steps: s1, a multi-source data fusion layer collects multi-source emergency data through a standardized interface, and fusion, cleaning and standardization processing are carried out on the collected data; S2, analyzing and processing standardized data through an emergency large model by an AI large model core layer, identifying an emergency event type and judging an event grade; The AI large model core layer combines the geographic information and the real-time traffic data, plans the optimal rescue route and matches the nearby … | N13: The AI large model core layer builds a dynamic emergency situation panorama by fusing multi-source data such as geographic information, traffic road conditions, emergency resource distribution, event details and the like in real time, models rescue planning into a multi-constraint optimization problem with the shortest overall response time, the highest resource utilization rate and the strongest path reliability as a core target on the basis, performs efficient solution by using a graph optimization and resource scheduling algorithm, and thus generates an integrated intelligent scheduling plan comprising an optimal travelling route … | O13: G06F-018/22, G06F-018/2433, G06F-018/25, G06N-005/04, G06N-020/00, G06Q-050/26 | P13: IT methods for management | R13: Chinese application based on an AI large model that fuses multi-source data (geographic, traffic, resource and event information), builds a situation picture and treats rescue planning as a multi-constraint optimisation problem, with emergency material tracking and communication-reliability features. Its legal status is lapsed and the state is dead, so it is low risk, but it still shows that large-model emergency platforms are known. The description is a broad management platform rather than a lightweight dispatch tool, and nothing in the extracted data indicates offline operation, retrieval of official procedures or Indian-language output. ResQ-MAR is narrower and more practical: eight agents with defined roles, a local Llama 3.1 model, NDMA-grounded retrieval, live web checks, voice and image intake, OSRM road routing and Telugu and Hindi dispatch with visual explanations. It can run on a single machine without cloud infrastructure.
A14: 10 | B14: =IF(LEFT(D14,2)="IN","India",IF(LEFT(D14,2)="US","USA",IF(LEFT(D14,2)="CN","China","Other"))) -> China | C14: Emergency cooperative scheduling strategy generation method based on swarm intelligence | D14: CN121936827 | E14: 46035 | F14: 46035 | G14: 46140 | H14: BEIJING QUNXIN SHIKONG INTELLIGENT TECHNOLOGY | I14: E CHAO | J14: Pending | K14: Alive | L14: The invention relates to the field of emergency management, in particular to an emergency cooperative scheduling strategy generation method based on swarm intelligence. The method comprises the following steps: acquiring multi-source data of each agent, preprocessing the multi-source data, and feeding back the preprocessed multi-source data to the corresponding agent; the intelligent agent generates a preliminary scheduling strategy according to the received multi-source data, and updates and maintains a strategy distribution snapshot of an edge node in the preliminary scheduling strategy; and obtaining an evolution path of the secondary disaster, inputting the evolution path of the secondary disaster, the preprocessed multi-source data and the strategy distribution snapshot of the edge node into the federal depth Q network model, and generating a collaborative scheduling strategy. In this way, the technical problems that structural obstacles exist in data integration and sharing facing emergency scenes, allocation and scheduling of computing resources are difficult to meet dynamic and high-timeliness requirements of emergency responses, and the overall toughness and cooperative capacity of a system are insufficient are solved. | M14: 1. The method for generating the emergency cooperative scheduling strategy based on the group intelligence is characterized by comprising the following steps of: Acquiring multi-source data of each intelligent agent, preprocessing the multi-source data, and feeding back the multi-source data to the corresponding intelligent agent; generating a preliminary scheduling strategy by the intelligent agent according to the received multi-source data, and updating and maintaining strategy distribution snapshots of edge nodes in the preliminary scheduling strategy by using a lightweight distributed account book; and acquiring an evolution path of the … | N14: The above and other features, advantages and aspects of embodiments of the present invention will become more apparent by reference to the following detailed description when taken in conjunction with the accompanying drawings. The local DQN model periodically (for example, every 5 minutes) uploads the gradient parameters output in training to the cloud, and the federal evolution center of the cloud integrates all the uploaded gradient parameters by using a differential privacy gradient aggregation algorithm to generate a better global model, namely, a global evolution strategy model, wherein the performance and generalization capability of … | O14: G06F-009/54, G06F-017/16, G06F-017/18, G06F-021/62, G06F-030/23, G06N-003/006, G06N-003/042, G06N-003/0442, G06N-003/0464, G06N-005/01, G06N-020/00, G06Q-010/04, G06Q-010/0631, G06Q-010/0639, G06Q-050/26, H04L-067/60 | P14: Digital communication; IT methods for management | R14: Pending Chinese method that generates emergency cooperative scheduling strategies using swarm intelligence. Each agent preprocesses multi-source data, forms a preliminary strategy, and edge-node strategy snapshots are maintained, with local DQN models periodically uploading gradients to a cloud federated evolution centre that also models secondary disaster evolution. The approach depends on reinforcement-learning training, edge nodes and a cloud aggregation centre, so it is heavy to deploy and exposed to connectivity loss. ResQ-MAR provides swarm behaviour through conversation between role-specialised LLM agents, with no gradient training and no cloud centre. Everything essential runs locally: Llama 3.1 through Ollama, ChromaDB, and OSRM routing. It adds natural-language intake from voice and images, grounding in official NDMA protocols, live web verification before routing, and Telugu and Hindi dispatch, which the Chinese method does not describe.
A15: 11 | B15: =IF(LEFT(D15,2)="IN","India",IF(LEFT(D15,2)="US","USA",IF(LEFT(D15,2)="CN","China","Other"))) -> China | C15: Beidou positioning-based intelligent scheduling method and related equipment for emergency rescue vehicles | D15: CN121481199 | E15: 46034 | F15: 46034 | G15: 46105 | H15: SHENZHEN ZHAOYUAN TECHNOLOGY | I15: LIN JIESHENG; MOU LIANJUN; ZHAO PENG | J15: Granted | K15: Alive | L15: The invention discloses an emergency rescue vehicle intelligent scheduling method based on Beidou positioning and related equipment, and relates to the technical field of emergency management, the emergency rescue vehicle intelligent scheduling method based on Beidou positioning comprises the following steps: obtaining multi-mode state sensing data returned by a plurality of emergency rescue nodes in real time, the multi-modal state sensing data is composed of Beidou high-precision positioning information and a space-time label; the multi-modal state sensing data is input into a preset intelligent scheduling model, a dynamic vehicle scheduling strategy and collaborative path planning are generated, and the intelligent scheduling model is obtained through pre-training based on historical disaster situation data, a rescue resource game relationship and a group survival entropy optimization target; and sending a scheduling instruction to a corresponding target emergency rescue node according to the dynamic vehicle scheduling strategy and the cooperative path planning. According to the invention, the technical problem of low scheduling efficiency in a multi-concurrence scene is solved. | M15: 1. The intelligent dispatching method for the emergency rescue vehicle based on Beidou positioning is characterized by comprising the following steps of: acquiring multi-mode state sensing data transmitted back by a plurality of emergency rescue nodes in real time, wherein the multi-mode state sensing data consists of Beidou high-precision positioning information and space-time labels; The step of acquiring the multi-mode state sensing data transmitted back in real time by the plurality of emergency rescue nodes comprises the following steps: constructing a node agent training frame based on federal causal sensing, wherein each emergency … | N15: It can be appreciated that this step utilizes pre-trained models to place real-time situation data into a dynamic environment simulating multi-party gaming for computation. It will be appreciated that this step is a key element in putting the calculated optimal strategy into practice. Illustratively, one high frequency rule extracted from the global causal knowledge graph is that if the damage rate of the target area communication base station is more than 60%, a scout node relying on real-time video backhaul is assigned to go, and the task failure probability is increased. The application can be understood that a 'data-driven dynamic game … | O15: G06N-003/092, G06N-003/096, G06N-005/04, G06Q-010/047, G06Q-010/0631 | P15: IT methods for management | R15: Granted Chinese method for scheduling emergency rescue vehicles using Beidou high-precision positioning. Multimodal state data returned by rescue nodes, tagged with position and time, goes into a scheduling model that produces a dynamic vehicle strategy and collaborative paths, supported by a causal knowledge graph and a game-style simulation. It is strong where that satellite positioning infrastructure and node hardware exist, but it is tied to that ecosystem and does not describe citizen voice or photo reports, official Indian protocols or regional languages. ResQ-MAR needs only the coordinates in the report, or those the Metadata agent extracts from text, audio or an image, and routes on open OpenStreetMap data through a self-hosted OSRM server. Plans are grounded in NDMA procedures and live web context, hazard zones are checked with shapely, and dispatch is translated into Telugu and Hindi, with explainable flowcharts for human overseers.
A16: 12 | B16: =IF(LEFT(D16,2)="IN","India",IF(LEFT(D16,2)="US","USA",IF(LEFT(D16,2)="CN","China","Other"))) -> China | C16: Intelligent emergency response method based on multi-agent simulation | D16: CN121146320 | E16: 45859 | F16: 45859 | G16: 46007 | H16: ZHEJIANG UNIVERSITY | I16: WU CHAO; TANG YINING | J16: Pending | K16: Alive | L16: The invention discloses an intelligent emergency response method based on multi-agent simulation. The method comprises the steps of simulating a human emergency command system for an emergent emergency event, constructing a three-layer organization structure comprising a command center, a decision-making layer and an execution layer, distributing roles and responsibilities for each layer of intelligent agents, and configuring a shared database for storing and sharing information and knowledge among the intelligent agents; multi-agent cooperation is carried out, and the situation description of the emergency event is updated in an iteration mode so as to optimize the generated emergency response strategy; and after a final updated emergency response strategy is formed, the intelligent agents of all levels reflect the emergency response process, the reflection result and new knowledge are processed in a structured mode and updated to the shared database, and intelligent emergency response based on multi-agent simulation is completed. | M16: 1. An intelligent emergency response method based on multi-agent simulation is characterized by comprising the following steps: S1, simulating a human emergency command system aiming at an emergency event, constructing a three-layer organization structure comprising a command center, a decision layer and an execution layer, distributing roles and responsibilities for each level of agents, and simultaneously configuring a shared database for storing and sharing information and knowledge among the agents; S2, after each level of intelligent agents acquire a text simulation instruction containing initial situation description of an emergency … | N16: His task is to keep a good communication with the media, ensure that the public gets accurate information while avoiding the spread of panic emotions, he will analyze and provide decision advice based on the current situation. The information sharing and coordination mechanism reduces redundant work, improves efficiency, and is beneficial to reducing environmental pollution and resource consumption. The invention has the advantages of simplicity, convenience, easiness in use and high automation and intelligent level. If difficulty is encountered, the command center is immediately notified of the request for resource or instruction adjustment … | O16: G06N-003/006, G06N-003/0455, G06N-005/01, G06N-005/04, G06Q-010/0631, G06Q-050/26 | P16: IT methods for management | R16: Pending Chinese method from Zhejiang University that uses multi-agent simulation of a human command structure: a command centre, decision layer and execution layer, each with assigned roles, sharing a database and iteratively refining the situation description to optimise the emergency response. It is the closest conceptual match to role-based agent teams. Its emphasis is on simulating command organisation and producing response schemes, and the extracted data does not show integration with audio transcription, image assessment, retrieval of official standard procedures, road-level routing or translation. ResQ-MAR assigns each of eight agents a concrete operational tool: Whisper, Gemini Vision, JSON metadata extraction, a live web search, ChromaDB retrieval of NDMA procedures, OSRM routing and a translation agent. The outcome is an executable, localised dispatch plan rather than a simulated command exercise, and it runs on local infrastructure.
... A22: 18 | B22: =IF(LEFT(D22,2)="IN","India",IF(LEFT(D22,2)="US","USA",IF(LEFT(D22,2)="CN","China","Other"))) -> China | C22: Multi-agent model system and method for emergency decision-making assistance | D22: CN117764162 | E22: 45286 | F22: 45286 | G22: 45377 | H22: DS INFORMATION TECHNOLOGY | I22: HE ZHIDONG; CHEN HAO; FU CHENGPENG; DU WEN; WANG JUQUAN; LIANG ZHENG; YANG BO; LIU LIANGLIANG; ZHAO FUWANG; LI ZHIYUAN; QIU XIANGPING; LEI TING; PENG MINGXI; LIN YONGSHENG; CHEN JIAN | J22: Revoked | K22: Dead | L22: The invention discloses a multi-agent model system for emergency decision assistance. The multi-agent model system comprises a plurality of large language models for optimizing specific tasks. The invention further discloses an auxiliary multi-agent model method for emergency decision making. The method comprises the steps that external emergency information is received, preliminary rescue strategy information is generated through a rescue role Agent, the external emergency information is received, and situation awareness information is generated through a situation awareness role Agent and an external tool library; generating a preliminary rescue decision through a decision role Agent according to the preliminary rescue strategy information, the situation awareness information and the external emergency information; using an external knowledge base to generate emergency suggestion information through an expert role Agent according to the preliminary rescue decision and situation awareness information; according to the emergency suggestion information, final rescue decision information is generated through a decision role Agent; and executing according to the final rescue decision information. | M22: 1. A multi-agent model system for emergency decision assistance, comprising: the plurality of large language models optimized for specific tasks specifically comprise: rescue role Agent, decision role Agent, expert role Agent, situation awareness role Agent; the rescue role Agent receives external emergency information to generate preliminary rescue strategy information, executes the preliminary rescue strategy information according to final rescue decision information generated by the decision role Agent, and sends the executed external emergency information to the decision role Agent; the situation awareness role Agent receives the … | N22: (1) The method has the advantages that the universal common sense capability and the thinking chain capability of the large model are utilized, the natural language interaction capability is realized, and the autonomy and the logic association of the emergency decision process are realized. The technical bottlenecks of the existing emergency decision-oriented proxy model include: a) Knowledge is underutilized: the knowledge base set by the traditional emergency agent model is mainly in rule configuration, and mainly provides a basic judging function for decision making, and does not utilize the current massive external knowledge, common … | O22: G06F-016/25, G06F-040/205, G06N-005/025, G06N-005/04 | P22: Computer technology | R22: Chinese multi-agent model system for emergency decision assistance, with large language models acting as rescue, decision, expert and situation-awareness role agents that use an external tool library. Its legal status is revoked and the state is dead, so it is low risk, but it shows that role-based LLM agents for emergencies are not new in themselves. The novelty of ResQ-MAR should therefore be stated as the specific combination rather than the multi-agent idea alone. It assists decisions only, whereas ResQ-MAR completes the chain: Whisper voice intake, Gemini Vision severity scoring, JSON metadata, shapely hazard-zone checks, NDMA retrieval through ChromaDB, live web verification, local OSRM routing with blockage recalculation, Telugu and Hindi dispatch and flowchart explanations. It also runs on a local Llama 3.1 model, which supports offline operation.

Sheet Summary
A1: Summary of the Questel Patent Set
A3: By country | B3: Patents | C3: Check: every total above should equal the number of rows on the Patent Report sheet.
A4: India | B4: =COUNTIF('Patent Report'!$B$5:$B$22,A4) -> 3 | C4: ="Rows on report: "&COUNTA('Patent Report'!$D$5:$D$22) -> Rows on report: 18
A5: USA | B5: =COUNTIF('Patent Report'!$B$5:$B$22,A5) -> 3
A6: China | B6: =COUNTIF('Patent Report'!$B$5:$B$22,A6) -> 12
A7: Total | B7: =SUM(B4:B6) -> 18
A9: By legal status | B9: Patents
A10: Granted | B10: =COUNTIF('Patent Report'!$J$5:$J$22,A10) -> 6
A11: Pending | B11: =COUNTIF('Patent Report'!$J$5:$J$22,A11) -> 9
A12: Lapsed | B12: =COUNTIF('Patent Report'!$J$5:$J$22,A12) -> 2
A13: Revoked | B13: =COUNTIF('Patent Report'!$J$5:$J$22,A13) -> 1
A14: Total | B14: =SUM(B10:B13) -> 18
A16: By legal state | B16: Patents
A17: Alive | B17: =COUNTIF('Patent Report'!$K$5:$K$22,A17) -> 15
A18: Dead | B18: =COUNTIF('Patent Report'!$K$5:$K$22,A18) -> 3
A19: Total | B19: =SUM(B17:B18) -> 18
A21: Baseline used for the Remarks (ResQ-MAR features)
A22: 1. 8-agent Microsoft AutoGen swarm (Voice, Vision, Intake, Metadata, LiveAwareness, Planner, Router, Comms)
A23: 2. Whisper voice intake and Gemini Vision damage-severity scoring from photos
A24: 3. Strict JSON metadata with shapely hazard-zone checks (flood, cyclone, seismic GeoJSON)
A25: 4. ChromaDB retrieval of NDMA standard operating procedures before planning (agentic RAG)
A26: 5. Live web/weather context injection (DuckDuckGo + Groq) to avoid routing into active hazards
A27: 6. Self-hosted OSRM (Multi-Level Dijkstra) routing with road-blockage recalculation
A28: 7. GPS-state based regional-language dispatch (Telugu, Hindi and other Indian languages)
A29: 8. MermaidJS explainability flowcharts; local Llama 3.1 (Ollama) so core operation can work offline
A31: Notes and assumptions
A32: 1. Source: two Questel Orbit exports supplied by the student (3 Indian patents and 15 international patents); no patents were added or removed.
A33: 2. Ordering: the 3 Indian patents are placed first; the other 15 keep the order of the Questel export.
... A38: 7. Multi-agent LLM emergency systems already exist in the prior art; the novelty argument rests on the specific combination listed above, not on the multi-agent idea alone.

Sheet Full Text
A1: Publication No. | B1: Title | C1: Abstract (full) | D1: Independent Claims (full) | E1: Advantages / Previous Drawbacks (full)
A2: IN202511043796 | B2: A system and a method for reinforcement learning-based natural disaster relief coordination system | C2: The present invention relates to a method and system for a reinforcement learning-based natural disaster relief coordination system. The invention involves a multi-agent reinforcement learning (MARL) system for natural disaster rescue scenarios, a two-tiered decision-making framework comprising a strategic level for global resource distribution and a tactical level for localised resource optimization. This works as a cohesive state representation with heterogeneous data sources, encompassing environmental conditions, victim status, and geographic constraints, for emergency response scenarios. The system development conditions are replicated with actual disaster dynamics and survivor profiles; therefore, this facilitates real-time adaptive decision-making in the context of evolving crisis conditions, ultimately contributing to improved outcomes in emergency management. | D2: 1. A system for a reinforcement learning-based natural disaster relief coordination, comprising: a) a hierarchical multi-agent architecture; b) a state representation module; c) an action space enabling agents; d) a prioritization mechanism; e) and a learning module implementing; wherein the system operates under constrained communication conditions and is trained using simulation data for real-time, adaptive response in evolving disaster environments. | E2: Inter-coordination among various stakeholders, such as government departments, NGOs, and volunteers, is still a problem, leading to disjointed implementation and inefficient response. The most critical problem of victim prioritization based on their health condition as well as environmental conditions (such as proximity to safe locations) is still unresolved in existing systems
A3: IN202631101067 | B3: Intelligent rescue robot using NLP and optimization | C3: An intelligent rescue robotic system for disaster response comprises an antenna (201), IoT module (202), multimodal sensors (203), microprocessor (204), analog-to-digital converter (301), power arrangement including a step-down voltage regulator (206), lithium-ion battery (206), charge controller (207) and AC mains input (208), autonomous robot (209), touch-screen display (210), routes (211, 212), and cloud database (304). The system interprets textual and spoken emergency inputs using NLP to extract victim locations, hazards and environmental conditions, and combines the interpreted information with sensorderived data. A MILP optimization model determines rescue routes, task allocations and resource distributions under time, safety and resource constraints, while a MESSP module evaluates stochastic disaster scenarios. Dynamic path planning updates navigation according to hazards and changing sensor inputs, and the IoT-connected cloud platform coordinates robotic units for victim identification, supply delivery and guided evacuation. | D3: 1. An autonomous robotic system for disaster response, comprising: an antenna (201) operatively connected to an IoT module (202) for wireless communication with a cloud database (304); a plurality of multimodal sensors (203: S1-S6) configured to acquire environmental information comprising temperature, gas concentration, vibration, structural-integrity information, acoustic information, and visual or thermal information; an analog-to-digital converter (301) configured to digitize outputs received from the plurality of multimodal sensors (203: S1-S6) and communicate corresponding digital information through a GPIO interface; a microprocessor (204) communicatively coupled with the analog-to-digital converter (301), the IoT module (202) through a UART interface, and an autonomous robot (209) through TTL-level signals, and configured for sensor fusion, preprocessing, navigation-command generation, and rescue decision processing; a Natural Language Processing engine configured to interpret unstructured textual and spoken disaster inputs and extract contextual information comprising victim locations, environmental conditions, and hazards; an optimization and simulation module comprising a Mixed-Integer Linear Programming model configured to determine rescue routes, task distributions, resource allocations, and rescue strategies under time, safety, and resourceavailability constraints, and a Multi-Scenario Event-driven Simulation for Security and Performance module configured to evaluate stochastic disaster scenarios; a dynamic path-planning module configured to determine and dynamically update routes (211, 212) based on mission priority, visibility or sensing quality, measured or estimated risk, distance, expected traversal time, and estimated energy consumption; a power arrangement comprising a step-down voltage regulator (206), a lithiumion battery (206), a charge controller (207), and an AC mains input (208); the autonomous robot (209) comprising a touch-screen display (210) and an infrared camera configured to acquire thermal information for victim recognition and hazard assessment; and wherein the microprocessor (204) generates actuation and navigation commands for physical execution by the autonomous robot (209), and the IoT module (202) and cloud database (304) enable real-time data transmission, collaborative analysis, coordinated rescue operations, victim identification, supply delivery, and guided evacuation. 7. A method for autonomous robotic disaster response, comprising: receiving disaster-related information through an antenna (401) and an IoT module (402); interpreting unstructured textual or spoken disaster information using Natural Language Processing to determine victim locations, environmental conditions, and hazards; acquiring multimodal environmental information through a plurality of sensors (403: S1-S6), the multimodal environmental information comprising temperature, gas concentration, vibration, structural-integrity information, acoustic information, and visual or thermal information; acquiring thermal imagery through an infrared camera (410) associated with an autonomous robot (409); converting analog sensor outputs into digital information through an analog-todigital converter and providing the digital information to a microprocessor (404); processing the digital information through the microprocessor (404) for sensor fusion, preprocessing, and navigation-command generation; determining rescue routes, task allocations, and resource distributions using a Mixed-Integer Linear Programming model and evaluating stochastic disaster scenarios using a Multi-Scenario Event-driven Simulation for Security and Performance module; communicating actuation and navigation commands from the microprocessor (404) through a TTL interface to the autonomous robot (409); synchronizing mission information through the IoT module (402) and antenna (401); and supplying electrical power through a power-management subsystem (405-408) comprising a step-down voltage arrangement (406), lithium-ion battery (406), charge controller (407), and AC mains input (408). | E3: However, there is a demand for low-cost, easy to use, more easily adaptable technology.
